<?xml version="1.0" ?>
<robot name="iiwa" xmlns:xacro="http://ros.org/wiki/xacro">
  <xacro:arg name="mesh_path" default="." />
  <xacro:property name="max_effort" value="320"/>
  <xacro:property name="max_velocity" value="10"/>
  <xacro:property name="PI" value="3.1415926535897931"/>

    <!--joint between world and link_0-->
    <link name="world"/>
    <joint name="world_joint" type="fixed">
      <insert_block name="origin"/>
      <parent link="world"/>
      <child link="link_0"/>
    </joint>

    <link name="link_0">
      <inertial>
        <origin xyz="0 -0.01439 0.102503" rpy="0 0 0"/>
        <mass value="6.495"/>
        <inertia ixx="0.0690761441316632"  ixy="0"  ixz="0" iyy="0.0711085586914514" iyz="0" izz="0.0200625854402119"/>
      </inertial>

      <visual>
        <origin xyz="0 0 0" rpy="0 0 0"/>
        <geometry>
          <mesh filename="file://$(arg mesh_path)/meshes_iiwa/visual/base_link.dae"/>
        </geometry>
      </visual>

      <collision>
        <origin xyz="0 0 0" rpy="0 0 0"/>
        <geometry>
          <mesh filename="file://$(arg mesh_path)/meshes_iiwa/collision/link_0.dae"/>
        </geometry>
      </collision>

      <self_collision_checking>
        <origin xyz="0 0 0" rpy="0 0 0"/>
        <geometry>
          <capsule radius="0.15" length="0.25"/>
        </geometry>
      </self_collision_checking>

    </link>

    <!-- joint between link_0 and link_1 -->
    <joint name="joint_1" type="revolute">
      <parent link="link_0"/>
      <child link="link_1"/>
      <origin xyz="0 0 0.1525" rpy="0 0 0"/>
      <axis xyz="0 0 1"/>
      <limit lower="${-170 * PI / 180}" upper="${170 * PI / 180}"
             effort="${max_effort}" velocity="${max_velocity}" />
    </joint>

    <link name="link_1">
      <inertial>
        <origin xyz="0 -0.01439 0.102503" rpy="0 0 0"/>
        <mass value="6.495"/>
        <inertia ixx="0.0690761441316632"  ixy="0"  ixz="0" iyy="0.0711085586914514" iyz="0" izz="0.0200625854402119"/>
      </inertial>

      <visual>
        <origin xyz="0 0 0" rpy="0 0 0"/>
        <geometry>
          <mesh filename="file://$(arg mesh_path)/meshes_iiwa/visual/link_1.dae"/>
        </geometry>
      </visual>

      <collision>
        <origin xyz="0 0 0" rpy="0 0 0"/>
        <geometry>
          <mesh filename="file://$(arg mesh_path)/meshes_iiwa/collision/link_1.dae"/>
        </geometry>
      </collision>
    </link>

    <!-- joint between link_1 and link_2 -->
    <joint name="joint_2" type="revolute">
      <parent link="link_1"/>
      <child link="link_2"/>
      <origin xyz="0 0 0.2075" rpy="${PI / 2}   0 ${PI}"/>
      <axis xyz="0 0 1"/>
      <limit lower="${-120 * PI / 180}" upper="${120 * PI / 180}"
             effort="${max_effort}" velocity="${max_velocity}" />
    </joint>

    <link name="link_2">
      <inertial>
        <origin xyz="1.2e-05 0.06472 0.004804" rpy="0 0 0"/>
        <mass value="8.807"/>
        <inertia ixx="0.0824701683534692"  ixy="0"  ixz="0" iyy="0.0164110968055191" iyz="0" izz="0.0873510892661361" />
      </inertial>

      <visual>
        <origin xyz="0 0 -0.013" rpy="0 0 ${PI}"/>
        <geometry>
          <mesh filename="file://$(arg mesh_path)/meshes_iiwa/visual/link_2.dae"/>
        </geometry>
      </visual>

      <collision>
        <origin xyz="0 0 -0.013" rpy="0 0 ${PI}"/>
        <geometry>
          <mesh filename="file://$(arg mesh_path)/meshes_iiwa/collision/link_2.dae"/>
        </geometry>
      </collision>
    </link>

    <!-- joint between link_2 and link_3 -->
    <joint name="joint_3" type="revolute">
      <parent link="link_2"/>
      <child link="link_3"/>
      <origin xyz="0 0.2325 0" rpy="${PI / 2} 0 ${PI}"/>
      <axis xyz="0 0 1"/>
      <limit lower="${-170 * PI / 180}" upper="${170 * PI / 180}"
             effort="${max_effort}" velocity="${max_velocity}" />
    </joint>

    <link name="link_3">
      <inertial>
        <origin xyz="-2.08e-04 0.01601 0.087283" rpy="0 0 0"/>
        <mass value="2.8"/>
        <inertia ixx="0.0230152941318817"  ixy="0"  ixz="0" iyy="0.0228661554143474" iyz="0" izz="0.0554482283748983" />
      </inertial>

      <visual>
        <origin xyz="0 0 0" rpy="0 0 0"/>
        <geometry>
          <mesh filename="file://$(arg mesh_path)/meshes_iiwa/visual/link_3.dae"/>
        </geometry>
      </visual>

      <collision>
        <origin xyz="0 0 0" rpy="0 0 0"/>
        <geometry>
          <mesh filename="file://$(arg mesh_path)/meshes_iiwa/collision/link_3.dae"/>
        </geometry>
      </collision>
    </link>

   <!-- joint between link_3 and link_4 -->
    <joint name="joint_4" type="revolute">
      <parent link="link_3"/>
      <child link="link_4"/>
      <origin xyz="0 0 0.1875" rpy="${PI / 2} 0 0"/>
      <axis xyz="0 0 1"/>
      <limit lower="${-120 * PI / 180}" upper="${120 * PI / 180}"
             effort="${max_effort}" velocity="${max_velocity}" />
    </joint>

    <link name="link_4">
      <inertial>
        <origin xyz="-2.03e-04 0.098639 0.011478" rpy="0 0 0"/>
        <mass value="5.283"/>
        <inertia ixx="0.0472789668341968"  ixy="0"  ixz="0" iyy="0.00964726804146909" iyz="0" izz="0.0466529007761679" />
      </inertial>

      <visual>
        <origin xyz="0 0 -0.011" rpy="0 0 0"/>
        <geometry>
          <mesh filename="file://$(arg mesh_path)/meshes_iiwa/visual/link_4.dae"/>
        </geometry>
      </visual>

      <collision>
        <origin xyz="0 0 -0.011" rpy="0 0 0"/>
        <geometry>
          <mesh filename="file://$(arg mesh_path)/meshes_iiwa/collision/link_4.dae"/>
        </geometry>
      </collision>
    </link>

    <!-- joint between link_4 and link_5 -->
    <joint name="joint_5" type="revolute">
      <parent link="link_4"/>
      <child link="link_5"/>
      <origin xyz="0 0.2125 0" rpy="${-PI / 2} ${PI} 0"/>
      <axis xyz="0 0 1"/>
      <limit lower="${-170 * PI / 180}" upper="${170 * PI / 180}"
             effort="${max_effort}" velocity="${max_velocity}" />
    </joint>

    <link name="link_5">
      <inertial>
        <origin xyz="5.7e-05 0.014468 0.062938" rpy="0 0 0"/>
        <mass value="1.889"/>
        <inertia ixx="0.0138359953358589"  ixy="0"  ixz="0" iyy="0.0116859337751969" iyz="0" izz="0.00571863785412578" />
      </inertial>

      <visual>
        <origin xyz="0 0 0" rpy="0 0 ${PI}"/>
        <geometry>
          <mesh filename="file://$(arg mesh_path)/meshes_iiwa/visual/link_5.dae"/>
        </geometry>
      </visual>

      <collision>
        <origin xyz="0 0 0" rpy="0 0 ${PI}"/>
        <geometry>
          <mesh filename="file://$(arg mesh_path)/meshes_iiwa/collision/link_5.dae"/>
        </geometry>
      </collision>
    </link>

 <!-- joint between link_5 and link_6 -->
    <joint name="joint_6" type="revolute">
      <parent link="link_5"/>
      <child link="link_6"/>
      <origin xyz="0 0 0.1875" rpy="${PI / 2} 0 0"/>
      <axis xyz="0 0 1"/>
      <limit lower="${-120 * PI / 180}" upper="${120 * PI / 180}"
             effort="${max_effort}" velocity="${max_velocity}" />
    </joint>

    <link name="link_6">
      <inertial>
        <origin xyz="3.63e-04 0.016982 -0.019731" rpy="0 0 0"/>
        <mass value="2.32"/>
        <inertia ixx="0.00732758787216765"  ixy="0"  ixz="0" iyy="0.00477633755783711" iyz="0" izz="0.00606797638550296" />
      </inertial>

      <visual>
        <origin xyz="0 0 -0.061" rpy="0 0 ${PI}"/>
        <geometry>
          <mesh filename="file://$(arg mesh_path)/meshes_iiwa/visual/link_6.dae"/>
        </geometry>
      </visual>

      <collision>
        <origin xyz="0 0 -0.061" rpy="0 0 ${PI}"/>
        <geometry>
          <mesh filename="file://$(arg mesh_path)/meshes_iiwa/collision/link_6.dae"/>
        </geometry>
      </collision>
    </link>

 <!-- joint between link_6 and link_7 -->
    <joint name="joint_7" type="revolute">
      <parent link="link_6"/>
      <child link="link_7"/>
      <origin xyz="0 0.0796 0" rpy="${- PI / 2} ${PI} 0"/>
      <axis xyz="0 0 1"/>
      <limit lower="${-175 * PI / 180}" upper="${175 * PI / 180}"
             effort="${max_effort}" velocity="${max_velocity}" />
    </joint>

    <link name="link_7">
      <inertial>
        <origin xyz="0.001904 -9.3e-05 0.018862" rpy="0 0 0"/>
          <mass value="0.863"/>
        <inertia ixx="0.000884"  ixy="0"  ixz="0" iyy="0.000888" iyz="0" izz="0.001105" />
      </inertial>

      <visual>
        <origin xyz="0 0 0" rpy="0 0 0"/>
        <geometry>
          <mesh filename="file://$(arg mesh_path)/meshes_iiwa/visual/link_7.dae"/>
        </geometry>
      </visual>

      <collision>
        <origin xyz="0 0 0" rpy="0 0 0"/>
        <geometry>
          <mesh filename="file://$(arg mesh_path)/meshes_iiwa/collision/link_7.dae"/>
        </geometry>
      </collision>
    </link>

    <!-- Link: Link7 - Endeffector -->
    <joint name="joint_ee" type="fixed">
      <parent link="link_7"/>
      <child link="end_effector_link"/>
      <!--<origin xyz="0 0 0.045" rpy="0 -${PI/2} 0"/>-->
      <!-- <origin xyz="0 0 0.2174" rpy="0 -${PI/2} 0"/> -->
      <origin rpy="0 0 0" xyz="0 0 0.0615250000000001"/>
    </joint>

    <link name="end_effector_link">
    </link>

  <link name="robotiq_85_base_link">
    <visual>
      <geometry>
        <mesh filename="file://$(arg mesh_path)/meshes_gripper/visual/2f_85/robotiq_base.dae"/>
      </geometry>
    </visual>
    <collision>
      <geometry>
        <mesh filename="file://$(arg mesh_path)/meshes_gripper/collision/2f_85/robotiq_base.stl"/>
      </geometry>
    </collision>
    <inertial>
      <origin rpy="0 0 0" xyz="0.0 2.274e-05 0.03232288"/>
      <mass value="6.6320197e-01"/>
      <inertia ixx="5.1617816e-04" ixy="2.936e-8" ixz="0.0" iyy="5.8802208e-04" iyz="-3.2296e-7" izz="3.9462776e-04"/>
    </inertial>
  </link>
  <link name="robotiq_85_left_knuckle_link">
    <visual>
      <geometry>
        <mesh filename="file://$(arg mesh_path)/meshes_gripper/visual/2f_85/left_knuckle.dae"/>
      </geometry>
    </visual>
    <collision>
      <geometry>
        <mesh filename="file://$(arg mesh_path)/meshes_gripper/collision/2f_85/left_knuckle.stl"/>
      </geometry>
    </collision>
    <inertial>
      <origin rpy="0 0 0" xyz="0.01213197 0.0002 -0.00058647"/>
      <mass value="1.384773208e-02"/>
      <inertia ixx="3.5232e-7" ixy="0.0" ixz="1.1744e-7" iyy="2.31944e-6" iyz="0" izz="2.23136e-6"/>
    </inertial>
  </link>
  <link name="robotiq_85_right_knuckle_link">
    <visual>
      <geometry>
        <mesh filename="file://$(arg mesh_path)/meshes_gripper/visual/2f_85/right_knuckle.dae"/>
      </geometry>
    </visual>
    <collision>
      <geometry>
        <mesh filename="file://$(arg mesh_path)/meshes_gripper/collision/2f_85/right_knuckle.stl"/>
      </geometry>
    </collision>
    <inertial>
      <origin rpy="0 0 0" xyz="-0.01213197 0.0002 -0.00058647"/>
      <mass value="1.384773208e-02"/>
      <inertia ixx="3.5232e-7" ixy="0.0" ixz="-1.1744e-7" iyy="2.31944e-6" iyz="0.0" izz="2.23136e-6"/>
    </inertial>
  </link>
  <link name="robotiq_85_left_finger_link">
    <visual>
      <geometry>
        <mesh filename="file://$(arg mesh_path)/meshes_gripper/visual/2f_85/left_finger.dae"/>
      </geometry>
    </visual>
    <collision>
      <geometry>
        <mesh filename="file://$(arg mesh_path)/meshes_gripper/collision/2f_85/left_finger.stl"/>
      </geometry>
    </collision>
    <inertial>
      <origin rpy="0 0 0" xyz="0.00346899 -0.00079447 0.01867121"/>
      <mass value="4.260376752e-02"/>
      <inertia ixx="1.385792000000000e-05" ixy="0.0" ixz="-2.17264e-06" iyy="1.183208e-05" iyz="0.0" izz="5.19672e-06"/>
    </inertial>
  </link>
  <link name="robotiq_85_right_finger_link">
    <visual>
      <geometry>
        <mesh filename="file://$(arg mesh_path)/meshes_gripper/visual/2f_85/right_finger.dae"/>
      </geometry>
    </visual>
    <collision>
      <geometry>
        <mesh filename="file://$(arg mesh_path)/meshes_gripper/collision/2f_85/right_finger.stl"/>
      </geometry>
    </collision>
    <inertial>
      <origin rpy="0 0 0" xyz="-0.00346899 -5.53e-06 0.01867121"/>
      <mass value="4.260376752000000e-02"/>
      <inertia ixx="1.385792e-05" ixy="0.0" ixz="2.17264e-06" iyy="1.183208e-05" iyz="0.0" izz="5.19672e-06"/>
    </inertial>
  </link>
  <link name="robotiq_85_left_inner_knuckle_link">
    <visual>
      <geometry>
        <mesh filename="file://$(arg mesh_path)/meshes_gripper/visual/2f_85/left_inner_knuckle.dae"/>
      </geometry>
    </visual>
    <collision>
      <geometry>
        <mesh filename="file://$(arg mesh_path)/meshes_gripper/collision/2f_85/left_inner_knuckle.stl"/>
      </geometry>
    </collision>
    <inertial>
      <origin rpy="0 0 0" xyz="0.01897699 0.00015001 0.02247101"/>
      <mass value="2.969376448e-02"/>
      <inertia ixx="9.57136e-06" ixy="0.0" ixz="-3.93424e-06" iyy="8.69056e-06" iyz="0.0" izz="8.19144e-06"/>
    </inertial>
  </link>
  <link name="robotiq_85_right_inner_knuckle_link">
    <visual>
      <geometry>
        <mesh filename="file://$(arg mesh_path)/meshes_gripper/visual/2f_85/right_inner_knuckle.dae"/>
      </geometry>
    </visual>
    <collision>
      <geometry>
        <mesh filename="file://$(arg mesh_path)/meshes_gripper/collision/2f_85/right_inner_knuckle.stl"/>
      </geometry>
    </collision>
    <inertial>
      <origin rpy="0 0 0" xyz="-0.01926824 5.001e-05 0.02222178"/>
      <mass value="2.969376448e-02"/>
      <inertia ixx="9.42456e-06" ixy="0.0" ixz="3.9636e-06" iyy="8.69056e-06" iyz="0.0" izz="8.33824e-06"/>
    </inertial>
  </link>
  <link name="robotiq_85_left_finger_tip_link">
    <visual>
      <geometry>
        <mesh filename="file://$(arg mesh_path)/meshes_gripper/visual/2f_85/left_finger_tip.dae"/>
      </geometry>
    </visual>
    <collision>
      <geometry>
        <mesh filename="file://$(arg mesh_path)/meshes_gripper/collision/2f_85/left_finger_tip.stl"/>
      </geometry>
      <surface>
        <friction>
          <ode>
            <mu1>100000.0</mu1>
            <mu2>100000.0</mu2>
          </ode>
        </friction>
        <contact>
          <ode>
            <kp>1e+5</kp>
            <kd>1</kd>
            <soft_cfm>0</soft_cfm>
            <soft_erp>0.2</soft_erp>
            <minDepth>0.002</minDepth>
            <maxVel>0</maxVel>
          </ode>
        </contact>
      </surface>
    </collision>
    <inertial>
      <origin rpy="0 0 0" xyz="-0.01456706 -0.0008 0.01649701"/>
      <mass value="4.268588744e-02"/>
      <inertia ixx="1.048152e-05" ixy="0.0" ixz="3.5232e-6" iyy="1.197888e-05" iyz="0.0" izz="4.22784e-06"/>
    </inertial>
  </link>
  <link name="robotiq_85_right_finger_tip_link">
    <visual>
      <geometry>
        <mesh filename="file://$(arg mesh_path)/meshes_gripper/visual/2f_85/right_finger_tip.dae"/>
      </geometry>
    </visual>
    <collision>
      <geometry>
        <mesh filename="file://$(arg mesh_path)/meshes_gripper/collision/2f_85/right_finger_tip.stl"/>
      </geometry>
      <surface>
        <friction>
          <ode>
            <mu1>100000.0</mu1>
            <mu2>100000.0</mu2>
          </ode>
        </friction>
        <contact>
          <ode>
            <kp>1e+5</kp>
            <kd>1</kd>
            <soft_cfm>0</soft_cfm>
            <soft_erp>0.2</soft_erp>
            <minDepth>0.002</minDepth>
            <maxVel>0</maxVel>
          </ode>
        </contact>
      </surface>
    </collision>
    <inertial>
      <origin rpy="0 0 0" xyz="0.01456706 5e-05 0.01649701"/>
      <mass value="4.268588744e-02"/>
      <inertia ixx="1.048152e-05" ixy="0.0" ixz="-3.5232e-06" iyy="1.197888e-05" iyz="0.0" izz="4.22784e-06"/>
    </inertial>
  </link>
  <joint name="robotiq_85_base_joint" type="fixed">
    <parent link="end_effector_link"/>
    <child link="robotiq_85_base_link"/>
    <origin rpy="0 0 0" xyz="0 0 0"/>
  </joint>
  <joint name="robotiq_85_left_knuckle_joint" type="revolute">
    <parent link="robotiq_85_base_link"/>
    <child link="robotiq_85_left_knuckle_link"/>
    <axis xyz="0 -1 0"/>
    <origin rpy="0 0 0" xyz="0.03060114 0.0 0.05490452"/>
    <limit effort="50" lower="0.0" upper="0.8" velocity="0.5"/>
  </joint>
  <joint name="robotiq_85_right_knuckle_joint" type="revolute">
    <parent link="robotiq_85_base_link"/>
    <child link="robotiq_85_right_knuckle_link"/>
    <axis xyz="0 -1 0"/>
    <origin rpy="0 0 0" xyz="-0.03060114 0.0 0.05490452"/>
    <limit effort="50" lower="-0.8" upper="0.0" velocity="0.5"/>
    <mimic joint="robotiq_85_left_knuckle_joint" multiplier="-1"/>
  </joint>
  <joint name="robotiq_85_left_finger_joint" type="fixed">
    <parent link="robotiq_85_left_knuckle_link"/>
    <child link="robotiq_85_left_finger_link"/>
    <origin rpy="0 0 0" xyz="0.03152616 0.0 -0.00376347"/>
  </joint>
  <joint name="robotiq_85_right_finger_joint" type="fixed">
    <parent link="robotiq_85_right_knuckle_link"/>
    <child link="robotiq_85_right_finger_link"/>
    <origin rpy="0 0 0" xyz="-0.03152616 0.0 -0.00376347"/>
  </joint>
  <joint name="robotiq_85_left_inner_knuckle_joint" type="continuous">
    <parent link="robotiq_85_base_link"/>
    <child link="robotiq_85_left_inner_knuckle_link"/>
    <axis xyz="0 -1 0"/>
    <origin rpy="0 0 0" xyz="0.0127 0.0 0.06142"/>
    <mimic joint="robotiq_85_left_knuckle_joint"/>
  </joint>
  <joint name="robotiq_85_right_inner_knuckle_joint" type="continuous">
    <parent link="robotiq_85_base_link"/>
    <child link="robotiq_85_right_inner_knuckle_link"/>
    <axis xyz="0 -1 0"/>
    <origin rpy="0 0 0" xyz="-0.0127 0.0 0.06142"/>
    <mimic joint="robotiq_85_left_knuckle_joint" multiplier="-1"/>
  </joint>
  <joint name="robotiq_85_left_finger_tip_joint" type="continuous">
    <parent link="robotiq_85_left_finger_link"/>
    <child link="robotiq_85_left_finger_tip_link"/>
    <axis xyz="0 -1 0"/>
    <origin rpy="0 0 0" xyz="0.00563134 0.0 0.04718515"/>
    <mimic joint="robotiq_85_left_knuckle_joint" multiplier="-1"/>
  </joint>
  <joint name="robotiq_85_right_finger_tip_joint" type="continuous">
    <parent link="robotiq_85_right_finger_link"/>
    <child link="robotiq_85_right_finger_tip_link"/>
    <axis xyz="0 -1 0"/>
    <origin rpy="0 0 0" xyz="-0.00563134 0.0 0.04718515"/>
    <mimic joint="robotiq_85_left_knuckle_joint"/>
  </joint>

</robot>
